Workbook

Sheet داخلي
D1: بيانات العميل شهر 2 | J1: طريقة الدفع | N1: حساب الأوردر
B2: الحسابات | Q2: =SUBTOTAL(9,Q4:Q8) -> 0 | R2: =SUBTOTAL(9,'داخلي'!$R$4:$R$59) -> 275
A3: م | B3: التاريخ | C3: اسم المندوب | D3: اسم الراسل | E3: تليفون | F3: عنوان | G3: اسم المرسل اليه | H3: التليفون | I3: العنوان | J3: ف / كاش | K3: انستا | L3: نقدي | M3: أجل | N3: تمنه | O3: تم السداد | P3: توصيل2 | Q3: حساب المندوب | R3: صافي الشركة | S3: نيهال عبدالعزيز | T3: ليهم نقود | U3: صيانات وبنزين | V3: عليهم نقود
A4: 1 | B4: 46054 | C4: أبو عمار | D4: مني الخولي | F4: السلام | G4: المرور | H4: 0 | I4: 0 | M4: 35 | N4: 0 | O4: لا | P4: 35 | Q4: =V9244 | R4: ='داخلي'!$P4*25% -> 8.75 | S4: تروسيكل عم مسعد200
A5: 2 | B5: 46055 | C5: أبو عمار | D5: رضوي الخضري | F5: مساكن جامعه | I5: قولنجيل | L5: 45 | Q5: =V9245 | R5: ='داخلي'!$P5*25% -> 0 | S5: ومشوار 35
A6: 3 | B6: 46056 | C6: أبو عمار | D6: نورا برايا | E6: نتيجه ابنها | F6: حي الجامعه | G6: بيتها | H6: 0 | I6: الملك كامل | M6: 35+50رسوم | O6: لا | Q6: =V9246 | R6: ='داخلي'!$P6*25% -> 0
A7: 4 | B7: 46057 | C7: أبو عمار | D7: سماح سلامه | F7: الدراسات | I7: ش بورسعيد | L7: 35 | Q7: =V9247 | R7: ='داخلي'!$P7*25% -> 0
A8: 5 | B8: 46058 | C8: أبو عمار | D8: أسماء النجار | F8: ترب المسحيين | G8: أسماء النجار | L8: 40 | Q8: =V9248 | R8: ='داخلي'!$P8*25% -> 0
A9: 6 | B9: 46059 | C9: السيد | D9: د.اميره 1 | F9: الملك كامل | I9: مجمع المحاكم | K9: تم | N9: 35 | Q9: =V9249 | R9: ='داخلي'!$P9*25% -> 0 | S9: تروسيكل مسعد 300 | T9: الطيب 270 | U9: 50من خالد | V9: خصم250
A10: 7 | B10: 46060 | C10: السيد | D10: سماح سلامه مكتبه 2 | L10: 35 | Q10: =V9250 | R10: ='داخلي'!$P10*25% -> 0 | S10: مشواره 70 | V10: من السيد
A11: 8 | B11: 46061 | C11: السيد | D11: د.اميره 1 | F11: الملك كامل | I11: مجمع المحاكم | K11: تم | N11: 35 | Q11: =V9251 | R11: ='داخلي'!$P11*25% -> 0
A12: 9 | B12: 46062 | C12: السيد | D12: جرينتش خارجي | Q12: =V9252 | R12: ='داخلي'!$P12*25% -> 0
A13: 10 | B13: 46063 | C13: السيد | D13: سماح سلامه خارجي | O13: لا | Q13: =V9253 | R13: ='داخلي'!$P13*25% -> 0
A14: 11 | B14: 46064 | C14: السيد | Q14: =V9254 | R14: ='داخلي'!$P14*25% -> 0
A15: 12 | B15: 46065 | C15: السيد | D15: محمود سلطان | F15: محمود سلطان | I15: منيه سندوب | L15: 50 | O15: لا | Q15: =V9255 | R15: ='داخلي'!$P15*25% -> 0
A16: 13 | B16: 46066 | C16: السيد | D16: مني الخولي خارجي | O16: لا | Q16: =V9256 | R16: ='داخلي'!$P16*25% -> 0
A17: 14 | B17: 46067 | C17: عبود | D17: رحمه عميل نيو | G17: رحمه | P17: 35 | Q17: =V9257 | R17: ='داخلي'!$P17*25% -> 8.75
A18: 15 | B18: 46068 | C18: السيد | D18: هيفن خارجي | Q18: =V9258 | R18: ='داخلي'!$P18*25% -> 0
A19: 16 | B19: 46069 | C19: السيد | D19: الحاج اسامه | N19: 50 | O19: لا | Q19: =V9259 | R19: ='داخلي'!$P19*25% -> 0
A20: 17 | B20: 46070 | C20: السيد | O20: لا | Q20: =V9260 | R20: ='داخلي'!$P20*25% -> 0
A21: 18 | B21: 46071 | C21: السيد | D21: محمد ماني | L21: 35 | O21: لا | Q21: =V9261 | R21: ='داخلي'!$P21*25% -> 0
A22: 19 | B22: 46072 | C22: عبود | D22: اماني سنترال الجزيره | G22: العبور | P22: 30 | Q22: =V9262 | R22: ='داخلي'!$P22*25% -> 7.5 | T22: 270 ماني | V22: ماني عليه 30
A23: 20 | B23: 46073 | C23: عبود | D23: الحاج اسامه | F23: سندوب | P23: 40 | Q23: =V9263 | R23: ='داخلي'!$P23*25% -> 10 | V23: باقي حق مشوار طلخا
A24: 21 | B24: 46074 | C24: عبود | D24: الساعي | P24: 35 | Q24: =V9264 | R24: ='داخلي'!$P24*25% -> 8.75
A25: 22 | B25: 46075 | C25: عبود | Q25: =V9265 | R25: ='داخلي'!$P25*25% -> 0
A26: 23 | C26: السيد | D26: محمد ماني | M26: 270 | N26: 35 | Q26: =V9266 | R26: ='داخلي'!$P26*25% -> 0
A27: 24 | D27: محمد ماني | Q27: =V9267 | R27: ='داخلي'!$P27*25% -> 0
A28: 25 | C28: السيد | D28: ندي وجيه | M28: هتحول35 | Q28: =V9268 | R28: ='داخلي'!$P28*25% -> 0
A29: 26 | B29: 46054 | C29: خالد | D29: نهال عبدالعزيز | E29: فانوس | F29: شونه سندوب | G29: طفله57357 | M29: 0 | Q29: =V9269 | R29: ='داخلي'!$P29*25% -> 0
A30: 27 | B30: 46054 | E30: س | Q30: =V9270 | R30: ='داخلي'!$P30*25% -> 0
A31: 28 | B31: 46054 | C31: أبو عمار | D31: دكتوره اماني | F31: طلخا برج نوران | G31: ا.نهال | M31: 40 | O31: لا | Q31: =V9271 | R31: ='داخلي'!$P31*25% -> 0
A32: 29 | B32: 46054 | C32: أبو عمار | D32: سماح سلامه 2 | F32: الدرسات | I32: الأسواق | L32: 30 | Q32: =V9272 | R32: ='داخلي'!$P32*25% -> 0
A33: 30 | B33: 46054 | C33: أبو عمار | D33: ميرو ستور 1 | L33: 35 | Q33: =V9273 | R33: ='داخلي'!$P33*25% -> 0
A34: 31 | C34: أبو عمار | D34: هاله | K34: 40 | O34: نعم | Q34: =V9274 | R34: ='داخلي'!$P34*25% -> 0
A35: 32 | B35: 46054 | C35: أبو عمار | D35: ثلاجه نهال | M35: 50 | O35: لا | Q35: =V9275 | R35: ='داخلي'!$P35*25% -> 0
A36: 33 | B36: 46054 | C36: أبو عمار | D36: ام باسم | I36: طلخا | L36: 40 | Q36: =V9276 | R36: ='داخلي'!$P36*25% -> 0
A37: 34 | B37: 46054 | C37: أبو عمار | Q37: =V9277 | R37: ='داخلي'!$P37*25% -> 0
A38: 35 | C38: أبو عمار | E38: توتال 175 ج | F38: توتال صافي شغال425 | Q38: 320
A39: 36 | B39: 46054 | Q39: =V9279 | R39: 105
A40: 37 | B40: 46054 | Q40: =V9280 | R40: ='داخلي'!$P40*25% -> 0
...

Sheet خالد
A1: م | B1: التاريخ | C1: اليوم | D1: اسم المندوب | E1: اسم الراسل | F1: حساب الاوردر | G1: ملاحظات
A2: 1 | B2: 46082 | C2: الأحد | D2: خالد | E2: شيماء سليمان | F2: 560+35 | G2: .
A3: 2 | E3: الفتح | F3: عليه مشوار بوسطه 35
A4: 3 | E4: سينيه 35 | F4: داخلي
A5: 4 | E5: العصير -200 بودي
A6: 5 | E6: اظرف مكتبه لنهال | F6: 160- وعليها مشوار | G6: نهال عبدالعزيز
A7: 6 | E7: -160 بلبن ايهاب البوب
A8: 7 | E8: -50بنزين
A9: 8 | E9: -عرق سوس 25
A10: 9
A11: 10
A12: 11
A13: 12
A14: 13
A15: 14
A16: 15
E17: عهدة
E18: توتال | F18: 400
E19: الشغل
E20: القبض | F20: 250
E21: الصافي | F21: 150
A23: م | B23: التاريخ | C23: اليوم | D23: اسم المندوب | E23: اسم الراسل | F23: حساب الاوردر | G23: ملاحظات
A24: 1 | B24: 46083 | C24: الاثنين | E24: نيهال عبدالعزيز | F24: لنهي
A25: 2 | E25: شركه الميه دكتور سمير | F25: -100ج | G25: و50 مشوار حولت
A26: 3 | F26: نيهال عبدالعزيز
A27: 4 | E27: كارما والمقدم ووئام والتحصيل | F27: سماح سلامه
A28: 5 | E28: الادويه2 | F28: 500+35 اتحوال ليا | G28: 250+35
A29: 6 | E29: البراق نيهال | G29: نيهال عبدالعزيز
A30: 7 | E30: ياسمين قناه السويس | F30: 35
A31: 8 | E31: اخت نورا برايا | F31: الموقف | G31: عليها 35 توصيل ابنها بالوجبات
A32: 9 | E32: المقدم | F32: 45
A33: 10 | E33: كارما | F33: 40
A34: 11 | E34: اسماء النجار 3
A35: 12
A36: 13
A37: 14
A38: 15
E39: عهدة-50 بنزين
E40: توتال | F40: 255
E41: الشغل
...

Sheet عمر البربري
A1: حسابات شهر ( 3 )
A2: م | B2: التاريخ | C2: اليوم | D2: اسم المندوب | E2: اسم الراسل | F2: حساب الاوردر | G2: ملاحظات
A3: 1 | B3: 46083 | C3: الاثنين | D3: عمر البربري | E3: بلال فودة | F3: 35
A4: 2 | E4: حسن عبدالحفيظ | F4: 2×35=70
A5: 3 | E5: عبود | F5: -200
A6: 4 | E6: عهدة | F6: 600
A7: 5 | E7: اجمالي | F7: =35+70-200+600 -> 505
A8: 6 | E8: بنزين | F8: 30
A9: 7 | E9: بنزين | F9: 30
A10: 8 | E10: محمود الجمال | F10: 45
A11: 9 | E11: اجمالي | F11: =505-30-30+45 -> 490
A12: 10 | E12: معايا | F12: 200
A13: 11 | E13: باقي عليا | F13: 290
A14: 13 | E14: مشوار رشا | F14: 35
A15: 14 | E15: مشوار ام سيف لنهال | F15: 35
A16: 15 | E16: اجمالي التوصيل | F16: =35+70+45+70 -> 220
E17: قبض | F17: =F16*75/100 -> 165 | G17: عبدو له 360
A23: م | B23: التاريخ | C23: اليوم | D23: اسم المندوب | E23: اسم الراسل | F23: حساب الاوردر | G23: ملاحظات
A24: 1 | B24: 46084 | C24: الثلاثاء | D24: عمر البربري | E24: عصير نهال | F24: -330وعبدالرحمن 140
A25: 2 | E25: اميز | F25: 50
A26: 3 | E26: من الدمياطي 2 رز جمبري | F26: 50
A27: 4 | E27: عهدة جديد | F27: 500+50
A28: 5 | D28: 35 | E28: نورا برايا ل البرامات | F28: -250 | G28: علليها توصيل وعليها تمن البرامات 250
A29: 6 | D29: 70 | E29: نورا برايا ل الاستاد ب معاذ | F29: عليها مشوار رايح جاي مع انتظار لمدة 20 ديقيقة
A30: 7 | D30: 35 | E30: نورا برايا اللبن | F30: مكنش في لبن عند الراجل بس عليها مشوار
A31: 8 | D31: 80 | E31: نورا برايا | F31: -490 من ملفوف وعليها مشوار رايح جاي
A32: 9
A33: 10 | E33: بنزين | F33: -20
A34: 13 | E34: باقي 215 | F34: =490-330-140+50+50+550-250-490+305-20 -> 215
A35: 14 | E35: معايا | F35: 0
A36: 15 | E36: عليا | F36: 215
E37: قبض 100+165 من اليوم الي قبله | F37: 265 اجمالي
E38: نورا برايا 6 | F38: دا حسابي بدون حساب اوردرات نورا برايا
E39: انت ليك 220
E40: توتال شغل 355 | F40: قبض 270
E41: انت ليك 490
A43: م | B43: التاريخ | C43: اليوم | D43: اسم المندوب | E43: اسم الراسل | F43: حساب الاوردر | G43: ملاحظات
A44: 1 | B44: 46085 | C44: الأربعاء | D44: عمر البربري | E44: انت ليك 490
A45: 2 | D45: عمر البربري
A46: 3 | D46: عمر البربري
...

Sheet عبود
A1: 0
A2: م | B2: التاريخ | C2: اليوم | D2: اسم المندوب | E2: اسم الراسل | F2: حساب الاوردر | G2: ملاحظات
A3: 1 | B3: 46025 | C3: الأحد | F3: ومعاه 335
A4: 2 | E4: لينك | F4: 30
A5: 3 | E5: حسن عبدالحفيظ | F5: 35+35
A6: 4 | E6: جي ار | F6: 35
A7: 5 | E7: سماح سلامه | F7: 30
A8: 6 | E8: ظرف نهال 3 واتس واحد | F8: وصلها
A9: 7 | E9: دونتس | F9: 35 و20 قديمه
A10: 8 | E10: حمدي مجمع المحاكم ت نيهال | F10: ام ليالي وام ابراهيم | G10: نيهال عبدالعزيز
A11: 9 | E11: محمد وجيه ادويه | F11: 1100+35+500+35
A12: 10
A13: 11
A14: 12
A15: 13
A16: 14
A17: 15
E18: عهدة | F18: 335
E19: توتال | F19: 2225
E20: الشغل | F20: 375
E21: القبض | F21: 280
E22: الصافي | F22: 1945
A24: م | B24: التاريخ | C24: اليوم | D24: اسم المندوب | E24: اسم الراسل | F24: حساب الاوردر | G24: ملاحظات
A25: 1 | B25: 46056 | C25: الاثنين | E25: وسا م | F25: -125وعليها 40 | G25: عليه100
A26: 2 | E26: اسماء النجار 2 | F26: عيها 70
A27: 3 | E27: نورا برايا | F27: الموقف عليها 35
A28: 4 | E28: سوق الخواجات | F28: 50
A29: 5 | E29: المطافي الضحي | F29: حولت 35
A30: 6 | E30: بساط ادويه | F30: 1200+100
A31: 7
A32: 8
A33: 9
A34: 10
A35: 11
A36: 12
A37: 13
A38: 14
A39: 15
E40: عهده 500+200
E41: توتال1925
...

Sheet ابو عمار
A1: حسابات شهر ( 3 )
A2: م | B2: التاريخ | C2: اليوم | D2: اسم المندوب | E2: اسم الراسل | F2: حساب الاوردر | G2: ملاحظات
A3: 1 | B3: 46082 | C3: الأحد | D3: ابو عمار | E3: الوجبه للخواجات | F3: 50
A4: 2 | E4: المقدم محمد بكري | F4: 40
A5: 3 | E5: شاوة بنفنوتي | F5: 90
A6: 4 | E6: لينك | F6: 50
A7: 5 | E7: ام باسم | F7: 385+40
A8: 6
A9: 7
A10: 8
A11: 9
A12: 10
A13: 11
A14: 12
A15: 13
A16: 14
A17: 15
E18: عهدة
E19: توتال655
E20: الشغل 270
E21: 205
E22: الصافي450
A24: م | B24: التاريخ | C24: اليوم | D24: اسم المندوب | E24: اسم الراسل | F24: حساب الاوردر | G24: ملاحظات
A25: 1 | B25: 46083 | C25: الاثنين | D25: ابو عمار | E25: الحاج اسامه | F25: 40
A26: 2 | D26: ابو عمار | E26: الفراخ الجمل 2 | F26: 80
A27: 3 | D27: ابو عمار | E27: الخضري | F27: 40
A28: 4 | D28: ابو عمار | E28: هند عاشور | F28: 35
A29: 5 | D29: ابو عمار | E29: تيته | F29: 40
A30: 6 | D30: ابو عمار | E30: الاوتبيس الجديد | F30: امال 35
A31: 7 | D31: ابو عمار | E31: اسماء النجار | F31: 50
A32: 8 | D32: ابو عمار | E32: سكه سندوب | F32: 40
A33: 9 | D33: ابو عمار | E33: الشيخ شريف | F33: الهديه 40 عليه
A34: 10 | D34: ابو عمار | E34: دونتس | F34: 30
A35: 11
A36: 12
A37: 13
A38: 14
A39: 15
E40: عهدة500
E41: توتال890
...

Sheet محمد الاسكندراني
A1: م | B1: التاريخ | C1: اليوم | D1: اسم المندوب | E1: اسم الراسل | F1: حساب الاوردر | G1: ملاحظات
A2: 1 | B2: 46100 | C2: الخميس | D2: محمد الاسكندراني | E2: شريف 50
A3: 2 | E3: نيو بيبي 80
A4: 3 | D4: . | E4: بلال فوده 50
A5: 4 | E5: لينك 100
A6: 5 | E6: طلخا للجلاء 50
A7: 6 | E7: مها سنتر النيل 420+40+120 | F7: 920
A8: 7 | E8: ام عمر 80
A9: 8 | E9: وسام 90
A10: 9 | E10: الحاج اسامه 1210+500+100
A11: 10 | E11: نيو بيبي 80+60 | F11: 120شحن
A12: 11 | E12: ام حمزه 40
A13: 12 | E13: ساره احمد ماهر 40
A14: 13
A15: 14
A16: 15
E17: عهدة
E18: توتال | F18: 4150
E19: الشغل | F19: 920
E20: القبض | F20: 690
E21: الصافي
A22: م | B22: التاريخ | C22: اليوم | D22: اسم المندوب | E22: اسم الراسل | F22: حساب الاوردر | G22: ملاحظات
A23: 1 | B23: 46104 | C23: الاثنين | D23: محمد الاسكندراني | E23: من المرور لميت حدر | F23: 40 | G23: امبارح
A24: 2 | E24: طلخا لتوريل | F24: 50 | G24: امبارح
A25: 3 | D25: . | E25: محل البان بدرة رايح عبدالسلام عارف | F25: 40
A26: 4 | E26: من النخلة لحي الجامعة | F26: 70
A27: 5 | E27: كوريان هاوس | F27: 850+50
A28: 6 | E28: عبدالسلام عارف لعوض اللله الجديد | F28: 825+40
A29: 7 | E29: التليفونات ريم الخولي من المشاية للبيت | F29: -300عليها مشوار
A30: 8 | E30: عيش من فينيسيا لنورا برايا | F30: وعليها مشوارين -150
A31: 9 | E31: من الموقف الجديد لنورا برايا | F31: -40 ابو يس وعليها مشوار
E32: عهدة | F32: 150
E33: توتال | F33: 1625
E34: الشغل | F34: 445
E35: القبض | F35: 335
E36: الصافي | F36: 1290
A38: م | B38: التاريخ | C38: اليوم | D38: اسم المندوب | E38: اسم الراسل | F38: حساب الاوردر | G38: ملاحظات
A39: 1 | B39: 46105 | C39: الثلاثاء | D39: محمد | E39: احمد ماهر | F39: 40
A40: 2 | E40: سندوب | F40: 50
A41: 3 | E41: عزبه الصفيح | F41: 50
...

Sheet السيد
A1: م | B1: التاريخ | C1: اليوم | D1: اسم المندوب | E1: اسم الراسل | F1: حساب الاوردر | G1: ملاحظات
A2: 1 | B2: 46082 | C2: الأحد | D2: السيد | E2: مني الخولي | F2: 35
A3: 2 | E3: نفين ايمن | F3: 30+35+35+30+30
A4: 3 | E4: نفين ايمن | F4: عليها 70
A5: 4 | E5: برايمذا 35+35
A6: 5 | E6: خاله نفين 30
A7: 6 | E7: الكفاله اسماء النجار 50
A8: 7 | E8: كفاله نوران 500 | F8: نهال عبدالعزيز
A9: 8 | E9: الدوا ايه اعشاب 500+35
A10: 9 | E10: نورا برايا -150 السواق 35
A11: 10
A12: 11
A13: 12
A14: 13
A15: 14
A16: 15
E17: عهدة
E18: توتال | F18: 1230
E19: الشغل | F19: 535
E20: القبض | F20: 400
E21: الصافي
A23: م | B23: التاريخ | C23: اليوم | D23: اسم المندوب | E23: اسم الراسل | F23: حساب الاوردر | G23: ملاحظات
A24: 1 | B24: 46083 | C24: الاثنين | D24: السيد | E24: نورا برايا | F24: المسجد حمد ماهر 30
A25: 2 | E25: فرارجي | F25: نهال عبدالعزيز ل ام حنان
A26: 3 | E26: اسماء النجار | F26: 3
A27: 4 | E27: وئام داخلي | F27: 500+35
A28: 5 | E28: جامبا العصير | F28: 240+35
A29: 6 | E29: خاله نفيتن | F29: 30
A30: 7
A31: 8
A32: 9
A33: 10
A34: 11
A35: 12
A36: 13
A37: 14
A38: 15
E39: عهدة | F39: صافي للشركه 70
E40: توتال | F40: 870
E41: الشغل | F41: 270
...

Sheet يوسف العيوطي
A2: م | B2: التاريخ | C2: اليوم | D2: اسم المندوب | E2: اسم الراسل | F2: حساب الاوردر | G2: ملاحظات
A3: 1 | B3: 46086 | C3: الخميس | D3: يوسف | E3: نورا برايا | F3: حي الجامعه | G3: 30
A4: 2 | E4: نورا برايا | F4: البطل | G4: عليها مشوار
A5: 3 | E5: الاطعام | F5: 3 | G5: نيهال عبدالعزيز
E6: عهدة420 | F6: سلف20
E7: توتال470
E8: الشغل 30
E9: القبض120
E10: الصافي350
A12: م | B12: التاريخ | C12: اليوم | D12: اسم المندوب | E12: اسم الراسل | F12: حساب الاوردر | G12: ملاحظات
A13: 1 | B13: 46087 | C13: الجمعه | D13: يوسف | E13: ميتشو | F13: 80 | G13: معاك350
A14: 2 | E14: بلبل فوده | F14: -260 و35
A15: 3 | E15: -40 عصير عبدالرحمن
A16: 4
A17: 5
A18: 6
A19: 7
A20: 8
A21: 9
A22: 10
A23: 11
A24: 12
A25: 13
A26: 14
A27: 15
E28: عهدة500+1000
E29: توتال165
E30: الشغل 115
E31: القبض85
E32: الصافي عليك 80 | G32: تمت التصفيه بمعرفه
G33: عبدالرحمن
A34: م | B34: التاريخ | C34: اليوم | D34: اسم المندوب | E34: اسم الراسل | F34: حساب الاوردر | G34: ملاحظات
A35: 1 | B35: 46088 | C35: السبت | D35: يوسف | E35: نورا برايا | F35: المسجد الاستاد | G35: عليها مشوار
A36: 2
A37: 3
A38: 4
A39: 5
A40: 6
A41: 7
A42: 8
...

Sheet ابو مكه 
B7: 46083 | E7: مشعل | F7: اشيكولاته | G7: نهال عبدالعزيز
E8: نهال عبدالعزيز | F8: بيلا -30
E9: نورا برايا | F9: موقف اسكندريه -150 | G9: 70
E10: نورا برايا | F10: المفتاح الموقف الجديد | G10: 50
E13: توتال 200
E14: شغل 200
E15: قبض 150
A24: م | B24: التاريخ | C24: اليوم | D24: اسم المندوب | E24: اسم الراسل | F24: حساب الاوردر | G24: ملاحظات
A25: 1 | B25: 46085 | C25: الأربعاء | D25: ابومكه | E25: رانيا حسين | F25: سلكا | G25: 500+100
A26: 2 | E26: براميذا | F26: 35
A27: 3 | E27: شريف نظارات | F27: 35
A28: 4 | E28: ادهم القعقاع | F28: هيحول 50
A29: 5
A30: 6 | E30: نورا برايا الحل القافل | F30: عليها مشوار
A31: 7
A32: 8
A33: 9
A34: 10 | E34: ايمان موافي | F34: 35
A35: 11 | E35: نورا برايا | F35: عليها 50 | G35: من الطميهي للبيت عنها
A36: 12 | E36: الساعي للدراسات | F36: 35 | G36: وعليه مشوار رجوع
A37: 13 | E37: مها سنتر النيل | F37: 35+1885
A38: 14
A39: 15
E40: عهدة | F40: حول 450
E41: توتال | F41: 2210
C42: 670 | E42: الشغل | F42: 410
C43: 220+ | E43: القبض | F43: 305
E44: الصافي
A46: م | B46: التاريخ | C46: اليوم | D46: اسم المندوب | E46: اسم الراسل | F46: حساب الاوردر | G46: ملاحظات
A47: 1 | B47: 46086 | C47: الخميس | E47: نورين مصطفي | F47: عليها 35
A48: 2 | E48: ايمان السلام | F48: 3 | G48: 105
A49: 3 | E49: سارة اسماعيل
A50: 4 | E50: أخت احمد الشرقاوي
A51: 5
A52: 6
A53: 7
A54: 8
A55: 9
A56: 10
A57: 11
...

Sheet عبدالرحمن جاد 
A1: حسابات شهر ( 4 )
A2: م | B2: التاريخ | C2: اليوم | D2: اسم المندوب | E2: اسم الراسل | F2: حساب الاوردر | G2: ملاحظات
A3: 1 | B3: 46089 | C3: الأحد | E3: لينك | F3: 35
A4: 2 | E4: 3 اطعام
A5: 3 | E5: من مبارك لمطعم مارشال | F5: 40
A6: 4 | E6: اسماء النجار | F6: 50
E7: عهدة | F7: 0
E8: توتال | F8: 125
E9: الشغل
E10: القبض
E11: الصافي

Sheet نيهال عبدالعزيز
D1: بيانات العميل شهر 2 | K1: طريقة الدفع | O1: حساب الأوردر
A2: م | B2: التاريخ | C2: اسم المندوب | D2: اسم الراسل | E2: بيان الاوردر | F2: تليفون | G2: عنوان | H2: اسم المرسل اليه | I2: التليفون | J2: العنوان | K2: ف / كاش | L2: انستا | M2: نقدي | N2: أجل | O2: تمنه | P2: تم السداد | Q2: توصيل2 | R2: حساب المندوب | S2: صافي الشركة
B3: 46054 | C3: خالد | D3: نهال عبدالعزيز | E3: فانوس | G3: شونه سندوب | H3: طفله57357 | O3: 775 | Q3: 35
B4: 46054 | E4: سحب فلوس خالد | N4: 35
B5: 46054 | E5: تروسيكل عم مسعد | M5: 300 | O5: 70
E6: ظرف د.امال | R6: ف المكتب
E7: استيكر نهال 2مشوار
A10: م | B10: التاريخ | C10: اسم المندوب | D10: اسم الراسل | E10: بيان الاوردر | F10: تليفون | G10: عنوان | H10: اسم المرسل اليه | I10: التليفون | J10: العنوان | K10: ف / كاش | L10: انستا | M10: نقدي | N10: أجل | O10: تمنه | P10: تم السداد | Q10: توصيل2 | R10: حساب المندوب | S10: صافي الشركة
B11: 46055 | D11: نهال عبدالعزيز | E11: شاحن انكر
B12: 46055 | E12: الاطعام
B13: 46055 | E13: سكر السيد
B14: 46055 | E14: سكر عبود
B15: 46055 | E15: سكر خالد
A19: م | B19: التاريخ | C19: اسم المندوب | D19: اسم الراسل | E19: بيان الاوردر | F19: تليفون | G19: عنوان | H19: اسم المرسل اليه | I19: التليفون | J19: العنوان | K19: ف / كاش | L19: انستا | M19: نقدي | N19: أجل | O19: تمنه | P19: تم السداد | Q19: توصيل2 | R19: حساب المندوب | S19: صافي الشركة
B20: 46056 | D20: نهال عبدالعزيز 3/2/2026 | E20: ادايدس
B21: 46056 | E21: ظرف كيك بوب
B22: 46056 | E22: ظرف لابريل
B23: 46056 | E23: ظرف الاسيوطي
B24: 46056 | E24: ظرف ساميه الجممل
B25: 46056 | E25: ظرف توريل
B26: 46056 | E26: سكر ش محمد\ فتحي 4 ك | F26: ام اسلام
A29: م | B29: التاريخ | C29: اسم المندوب | D29: اسم الراسل | E29: بيان الاوردر | F29: تليفون | G29: عنوان | H29: اسم المرسل اليه | I29: التليفون | J29: العنوان | K29: ف / كاش | L29: انستا | M29: نقدي | N29: أجل | O29: تمنه | P29: تم السداد | Q29: توصيل2 | R29: حساب المندوب | S29: صافي الشركة
B30: 46057 | D30: نهال عبدالعزيز4/2/2026 | E30: كفاله رحاب 3000
B31: 46057 | E31: كفاله عم طارق 1000
B32: 46057 | E32: كفاله محمد رمزي 1000
B33: 46057 | E33: فاتن ش عشر1500 | L33: 46058
B34: 46057 | E34: ظرف ساعه1.5
B35: 46057 | E35: ظرف الجلاء c&b
B36: 46057 | E36: ظرف مبارك
B37: 46057 | E37: عم خالد 1000
A39: م | B39: التاريخ | C39: اسم المندوب | D39: اسم الراسل | E39: بيان الاوردر | F39: تليفون | G39: عنوان | H39: اسم المرسل اليه | I39: التليفون | J39: العنوان | K39: ف / كاش | L39: انستا | M39: نقدي | N39: أجل | O39: تمنه | P39: تم السداد | Q39: توصيل2 | R39: حساب المندوب | S39: صافي الشركة
B40: 46058 | D40: نهال عبدالعزيز
B41: 46058 | D41: كفاله1000علاء | H41: يوم5
D42: اوردر ارامكس35
A49: م | B49: التاريخ | C49: اسم المندوب | D49: اسم الراسل | E49: بيان الاوردر | F49: تليفون | G49: عنوان | H49: اسم المرسل اليه | I49: التليفون | J49: العنوان | K49: ف / كاش | L49: انستا | M49: نقدي | N49: أجل | O49: تمنه | P49: تم السداد | Q49: توصيل2 | R49: حساب المندوب | S49: صافي الشركة
D50: نهال عبدالعزيز | H50: يوم6
A59: م | B59: التاريخ | C59: اسم المندوب | D59: اسم الراسل | E59: بيان الاوردر | F59: تليفون | G59: عنوان | H59: اسم المرسل اليه | I59: التليفون | J59: العنوان | K59: ف / كاش | L59: انستا | M59: نقدي | N59: أجل | O59: تمنه | P59: تم السداد | Q59: توصيل2 | R59: حساب المندوب | S59: صافي الشركة
D60: نهال عبدالعزيز
H61: يوم7
A69: م | B69: التاريخ | C69: اسم المندوب | D69: اسم الراسل | E69: بيان الاوردر | F69: تليفون | G69: عنوان | H69: اسم المرسل اليه | I69: التليفون | J69: العنوان | K69: ف / كاش | L69: انستا | M69: نقدي | N69: أجل | O69: تمنه | P69: تم السداد | Q69: توصيل2 | R69: حساب المندوب | S69: صافي الشركة
...

Sheet إبراهيم الدوكش
A1: حسابات شهر ( 3 )
A2: م | B2: التاريخ | C2: اليوم | D2: اسم المندوب | E2: اسم الراسل | F2: حساب الاوردر | G2: ملاحظات
A3: 1 | B3: 46089 | C3: الأحد | D3: ابراهيم | E3: بوسعيد ام يوسعيد | F3: 40 | G3: اول يوم شغل
A4: 2 | E4: حنان | F4: =35 -> 35
A5: 3 | E5: مها سنتر النيل | F5: 30+180
A6: 4 | E6: الحاج اسامه | F6: 50+500
A7: 5 | E7: امل رضا | F7: 35
A8: 6 | E8: سينيه | F8: 35
A9: 7 | E9: توريل | F9: 30
A10: 8 | E10: الجلاء لمحمد فتحي | F10: 30
A11: 9 | E11: د.نورا برايا | F11: الطعميه واللبن والعيش والبطاطس | G11: -220وعليها 2 مشوار 70
A12: 10 | E12: اسماء النجار | F12: 50
A13: 11
A14: 12
A15: 13
A16: 14
A17: 15
E18: عهدة | F18: 500
E19: توتال | F19: 1295
E20: الشغل | F20: 405
E21: القبض | F21: 305
E22: الصافي | F22: 990 | G22: تمت التصفيه بمعرفه عبدالرحمن
A25: م | B25: التاريخ | C25: اليوم | D25: اسم المندوب | E25: اسم الراسل | F25: حساب الاوردر | G25: ملاحظات
A26: 1 | B26: 46090 | C26: الإثنين | E26: محمد الساعي | F26: 35
A27: 2 | E27: ابو النجا | F27: 70
A28: 3 | E28: ابرار | F28: 35
A29: 4 | E29: ام مليكه | F29: 40
A30: 5 | E30: سماح سلامه | F30: 50
A31: 6 | E31: حسن عبدالحفيظ | F31: 30
A32: 7 | E32: ابراهيم لينك | F32: 40
A33: 8 | E33: أ.نهال عبد العزيز | F33: عليها30 | G33: 2 كيس من سمر المرسي من المكتب
A34: 9
A35: 10
A36: 11
A37: 12
A38: 13
A39: 14
A40: 15 | G40: تمت التصفيه بمعرفه خالد
E41: عهدة
E42: توتال | F42: 300
...

Sheet يوسف الصغير
A1: حسابات شهر ( 3 )
A2: م | B2: التاريخ | C2: اليوم | D2: اسم المندوب | E2: اسم الراسل | F2: حساب الاوردر | G2: ملاحظات
A3: 1 | B3: 46089 | C3: الأحد | E3: عمل 3 اوردرات ب 105 واخدتهم منه
A4: 2 | E4: اشتغل 3 ايام
A5: 3 | E5: من بكره اليوم الرابع
A6: 4
A7: 5
A8: 6
A9: 7
A10: 8
A11: 9
A12: 10
A13: 11
A14: 12
A15: 13
A16: 14
A17: 15
E18: عهدة
E19: توتال
E20: الشغل
E21: القبض
E22: الصافي
A25: م | B25: التاريخ | C25: اليوم | D25: اسم المندوب | E25: اسم الراسل | F25: حساب الاوردر | G25: ملاحظات
A26: 1 | B26: 46090 | C26: الإثنين
A27: 2
A28: 3
A29: 4
A30: 5
A31: 6
A32: 7
A33: 8
A34: 9
A35: 10
A36: 11
A37: 12
A38: 13
... A40: 15
E41: عهدة
E42: توتال
E43: الشغل
...

Sheet تجميعه لاكتر من مندوب
A1: م | B1: التاريخ | C1: اسم المندوب | D1: اسم الراسل | E1: تليفون | F1: عنوان | G1: اسم المرسل اليه | H1: التليفون | I1: العنوان | J1: ف / كاش | K1: انستا | L1: نقدي | M1: أجل | N1: تمنه | O1: تم السداد | P1: توصيل2 | Q1: حساب المندوب | R1: صافي الشركة | S1: حاله الاوردر
B2: 46060
C3: عمر العايق | D3: شيماء صبحي | E3: 1090771073 | F3: عزبه الشال | I3: 35فقط
C4: عمرو العايق | D4: سالي عاجل | E4: 1000703776 | F4: الاوتبيس الجديد | I4: 350+35
C5: عبود | D5: روشا يوسف | F5: جديله البحر | I5: 140+35 | S5: لا ترد
C6: عبود | D6: دينا علي | F6: احمد ماهر | I6: 650+35 | S6: بكرا
C7: عبود | D7: نرمين مجدي | F7: الاوتبيس قديم | I7: شحن فقط | S7: تم التسليم
B8: ب | C8: عبود | D8: د.نهال | F8: جديله رخام | I8: 135+35+ | S8: ليست موجوده
C9: خالد | D9: بوسي الزيني | F9: المطافي | I9: 200+35 | S9: بكرا
C10: خالد | D10: عبير إبراهيم | F10: النخله | I10: 1050+35 | S10: تم التسليم
C11: خالد | D11: بدون | F11: الجلاء | I11: شحن فقط | S11: تم التسليم
C12: خالد | D12: جاسمين | F12: احمد ماهر | I12: 350+35 | S12: تم التسليم
C13: خالد | D13: ساره محمد | F13: احمد ماهر | I13: 260+35 | K13: تم 260 | S13: تم التسليم
C14: خالد | D14: حنين متولي | F14: ساميه الجمل | I14: 150+35 | S14: بكرا
C15: خالد | D15: ايمان جمال | F15: السلخانه | I15: 550+35 | L15: 410+مرتجع | S15: تم التسليم
C16: أبو عمار | D16: أسماء الشوربجي | F16: الدرسات | I16: 280+35 | S16: لا ترد
C17: أبو عمار | D17: سمر سويلم | F17: توريل | I17: 430+35 | S17: بكرا
C18: أبو عمار | D18: عبير عادل | F18: بدون | I18: 1385+35 | S18: تم التسليم
C20: أبو عمار | D20: ايمان سامي | F20: مجمعالمحاكم | I20: 400+35 | N20: 150+مرتجع | S20: تم التسليم
C21: أبو عمار | D21: سولا سعد | F21: خطاب | I21: 250+35 | S21: تم التسليم
C22: بدون | D22: سميه الهلالي | F22: ساميه الجمل | G22: بكره
A24: ماني
A25: م | B25: التاريخ | C25: اسم المندوب | D25: اسم الراسل | E25: تليفون | F25: عنوان | G25: اسم المرسل اليه | H25: التليفون | I25: العنوان | J25: ف / كاش | K25: انستا | L25: نقدي | M25: أجل | N25: تمنه | O25: تم السداد | P25: توصيل2 | Q25: حساب المندوب | R25: صافي الشركة | S25: عجوزات / خصومات | T25: له
A26: 1 | B26: 46054 | D26: كات ليدي | N26: 500 | O26: لا | P26: 35 | S26: ماني عليه 30 | T26: 270 ماني
A27: 2 | B27: 46054 | D27: ماني | F27: الصدر | I27: الموقف الجديد | P27: 40 | S27: باقي حق مشوار طلخا
A28: 3 | B28: 46054 | H28: توتال 785 | I28: توتال شغال 355
A29: 4 | B29: 46054 | I29: قبض265
A30: 5
A31: 6
A32: 7
A33: 8
A34: 9
A35: 10
D36: عهدة
D37: توتال | E37: 785
D38: الشغل | E38: 355
D39: صافي | E39: 265
A40: م | B40: التاريخ | C40: اسم المندوب | D40: اسم الراسل | E40: تليفون | F40: عنوان | G40: اسم المرسل اليه | H40: التليفون | I40: العنوان | J40: ف / كاش | K40: انستا | L40: نقدي | M40: أجل | N40: تمنه | O40: تم السداد | P40: توصيل2 | Q40: حساب المندوب | R40: صافي الشركة | S40: عجوزات / خصومات | T40: له
C41: ابو يونس | D41: نهال عبدالعزيز | G41: ظرف نور موسي | I41: وادايدس
D42: نهال عبدالعزيز | G42: ادايدس
